[2016-10-21 09:46:30] [main] [ERROR] (_mysql_exceptions.OperationalError) (2006, 'MySQL server has gone away') [SQL: u'SELECT m_tbnetport.id AS m_tbnetport_id, m_tbnetport.`sPortName` AS `m_tbnetport_sPortName`, m_tbnetport.`sNetMask` AS `m_tbnetport_sNetMask`, m_tbnetport.`sWorkMode` AS `m_tbnetport_sWorkMode`, m_tbnetport.`iByManagement` AS `m_tbnetport_iByManagement`, m_tbnetport.`iAllowPing` AS `m_tbnetport_iAllowPing`, m_tbnetport.`iAllowTraceRoute` AS `m_tbnetport_iAllowTraceRoute`, m_tbnetport.`iAllowFlow` AS `m_tbnetport_iAllowFlow`, m_tbnetport.`iIPV4ConnectionType` AS `m_tbnetport_iIPV4ConnectionType`, m_tbnetport.`sIPV4Address` AS `m_tbnetport_sIPV4Address`, m_tbnetport.`sIPV4NextJump` AS `m_tbnetport_sIPV4NextJump`, m_tbnetport.`iIPV6ConnectionType` AS `m_tbnetport_iIPV6ConnectionType`, m_tbnetport.`sIPV6Address` AS `m_tbnetport_sIPV6Address`, m_tbnetport.`sIPV6NextJump` AS `m_tbnetport_sIPV6NextJump`, m_tbnetport.`iStatus` AS `m_tbnetport_iStatus` \nFROM m_tbnetport'] | args: ['CMD_NIC_FLUSH']
Traceback (most recent call last):
  File "/usr/local/bluedon/core/task.py", line 831, in run
    commands[args[0]](args[1:])
  File "/usr/local/bluedon/core/task.py", line 465, in proc_nic_flush
    insert_interfaces()
  File "/usr/local/bluedon/networking/fwdb.py", line 58, in insert_interfaces
    for instance in session.query(net_interface):
  File "build/bdist.linux-x86_64/egg/sqlalchemy/orm/query.py", line 2761, in __iter__
    return self._execute_and_instances(context)
  File "build/bdist.linux-x86_64/egg/sqlalchemy/orm/query.py", line 2776, in _execute_and_instances
    result = conn.execute(querycontext.statement, self._params)
  File "build/bdist.linux-x86_64/egg/sqlalchemy/engine/base.py", line 914, in execute
    return meth(self, multiparams, params)
  File "build/bdist.linux-x86_64/egg/sqlalchemy/sql/elements.py", line 323, in _execute_on_connection
    return connection._execute_clauseelement(self, multiparams, params)
  File "build/bdist.linux-x86_64/egg/sqlalchemy/engine/base.py", line 1010, in _execute_clauseelement
    compiled_sql, distilled_params
  File "build/bdist.linux-x86_64/egg/sqlalchemy/engine/base.py", line 1146, in _execute_context
    context)
  File "build/bdist.linux-x86_64/egg/sqlalchemy/engine/base.py", line 1341, in _handle_dbapi_exception
    exc_info
  File "build/bdist.linux-x86_64/egg/sqlalchemy/util/compat.py", line 202, in raise_from_cause
    reraise(type(exception), exception, tb=exc_tb, cause=cause)
  File "build/bdist.linux-x86_64/egg/sqlalchemy/engine/base.py", line 1139, in _execute_context
    context)
  File "build/bdist.linux-x86_64/egg/sqlalchemy/engine/default.py", line 450, in do_execute
    cursor.execute(statement, parameters)
  File "build/bdist.linux-x86_64/egg/MySQLdb/cursors.py", line 205, in execute
    self.errorhandler(self, exc, value)
  File "build/bdist.linux-x86_64/egg/MySQLdb/connections.py", line 36, in defaulterrorhandler
    raise errorclass, errorvalue
OperationalError: (_mysql_exceptions.OperationalError) (2006, 'MySQL server has gone away') [SQL: u'SELECT m_tbnetport.id AS m_tbnetport_id, m_tbnetport.`sPortName` AS `m_tbnetport_sPortName`, m_tbnetport.`sNetMask` AS `m_tbnetport_sNetMask`, m_tbnetport.`sWorkMode` AS `m_tbnetport_sWorkMode`, m_tbnetport.`iByManagement` AS `m_tbnetport_iByManagement`, m_tbnetport.`iAllowPing` AS `m_tbnetport_iAllowPing`, m_tbnetport.`iAllowTraceRoute` AS `m_tbnetport_iAllowTraceRoute`, m_tbnetport.`iAllowFlow` AS `m_tbnetport_iAllowFlow`, m_tbnetport.`iIPV4ConnectionType` AS `m_tbnetport_iIPV4ConnectionType`, m_tbnetport.`sIPV4Address` AS `m_tbnetport_sIPV4Address`, m_tbnetport.`sIPV4NextJump` AS `m_tbnetport_sIPV4NextJump`, m_tbnetport.`iIPV6ConnectionType` AS `m_tbnetport_iIPV6ConnectionType`, m_tbnetport.`sIPV6Address` AS `m_tbnetport_sIPV6Address`, m_tbnetport.`sIPV6NextJump` AS `m_tbnetport_sIPV6NextJump`, m_tbnetport.`iStatus` AS `m_tbnetport_iStatus` \nFROM m_tbnetport']
[2016-10-21 09:46:33] [main] [INFO] del_allow_manage and del_allow_ping
[2016-10-21 09:46:33] [main] [INFO] /home/ng_platform/bd_dpdk_warper/clients/port_config vEth5 10
[2016-10-21 09:46:33] [main] [INFO] config_iface: allow_ping `0` allow_manage `0`
[2016-10-21 09:46:33] [main] [INFO] config_iface: ipv6 allow_ping `0` allow_manage `0`
[2016-10-21 09:46:33] [main] [WARNING] device `vEth5` ip config `192.168.4.2/24` failed| RTNETLINK answers: File exists
[2016-10-21 09:46:33] [main] [INFO] iface `vEth5` del_ip: set([]) ===> add_ip: set([MyIP('192.168.4.2', '24')])
